Workbook
Name CALCULUS: Dashboard2[]
Name SegmentaçãodeDados_Meses__Data: #N/A
Name SegmentaçãodeDados_Tipo_Fluxo: #N/A

Sheet DB_MOVIMENTACAO
A1: ID_Transacao | B1: Data | C1: Tipo Fluxo | D1: ID Entidade | E1: Nome da Entidade | F1: ID Produto | G1: Descrição do Produto | H1: Quantidade | I1: Valor Unitário | J1: Valor Total | K1: Status Financeiro | L1: Status Logistico | M1: Previsão de Entrega | O1: Atualização randômica para as movimentações com ID entre T0021 a T1020
A2: T0001 | B2: 45658 | C2: Saida | D2: CLI005 | E2: =IF(Tabela_Movimentacao_Geral[[#This Row],[Tipo Fluxo]]="Saida",_xlfn.XLOOKUP(Tabela_Movimentacao_Geral[[#This Row],[ID Entidade]], Tabela_Clientes[ID_Cliente],Tabela_Clientes[Nome_Cliente],"Cliente não encontrado"),_xlfn.XLOOKUP(Tabela_Movimentacao_Geral[[#This Row],[ID Entidade]], Tabela_Fornecedores[ID_Fornecedor], Tabela_Fornecedores[Nome_Fantasia], "Fornecedor não encontrado")) -> Banco Futuro | F2: PROD006 | G2: =_xlfn.XLOOKUP(Tabela_Movimentacao_Geral[[#This Row],[ID Produto]], Tabela_Produtos[ID_Produto],Tabela_Produtos[Descricao_Produto],"Produto não encontrado") -> Notebook i7 16GB 512GB SSD | H2: 2 | I2: =_xlfn.XLOOKUP(Tabela_Movimentacao_Geral[[#This Row],[ID Produto]], Tabela_Produtos[ID_Produto],Tabela_Produtos[Preco_Unitario_Venda]) -> 5500 | J2: =Tabela_Movimentacao_Geral[[#This Row],[Quantidade]] * Tabela_Movimentacao_Geral[[#This Row],[Valor Unitário]] -> 11000 | K2: Pago | L2: Entregue | M2: =IF( $O$7="Desbloqueado", IF( Tabela_Movimentacao_Geral[[#This Row],[Tipo Fluxo]]="Entrada", Tabela_Movimentacao_Geral[[#This Row],[Data]] + _xlfn.XLOOKUP(Tabela_Movimentacao_Geral[[#This Row],[ID Entidade]],Tabela_Fornecedores[ID_Fornecedor],Tabela_Fornecedores[Lead_Time]), "N/A" ), Tabela_Movimentacao_Geral[[#This Row],[Previsão de Entrega]] ) -> N/A
A3: T0002 | B3: 45659 | C3: Entrada | D3: FORN001 | E3: =IF(Tabela_Movimentacao_Geral[[#This Row],[Tipo Fluxo]]="Saida",_xlfn.XLOOKUP(Tabela_Movimentacao_Geral[[#This Row],[ID Entidade]], Tabela_Clientes[ID_Cliente],Tabela_Clientes[Nome_Cliente],"Cliente não encontrado"),_xlfn.XLOOKUP(Tabela_Movimentacao_Geral[[#This Row],[ID Entidade]], Tabela_Fornecedores[ID_Fornecedor], Tabela_Fornecedores[Nome_Fantasia], "Fornecedor não encontrado")) -> TechFlow Solucoes | F3: PROD001 | G3: =_xlfn.XLOOKUP(Tabela_Movimentacao_Geral[[#This Row],[ID Produto]], Tabela_Produtos[ID_Produto],Tabela_Produtos[Descricao_Produto],"Produto não encontrado") -> Monitor 24 pol Full HD | H3: 10 | I3: =_xlfn.XLOOKUP(Tabela_Movimentacao_Geral[[#This Row],[ID Produto]], Tabela_Produtos[ID_Produto],Tabela_Produtos[Preco_Unitario_Venda]) -> 850 | J3: =Tabela_Movimentacao_Geral[[#This Row],[Quantidade]] * Tabela_Movimentacao_Geral[[#This Row],[Valor Unitário]] -> 8500 | K3: Pendente | L3: Aguardando | M3: =IF( $O$7="Desbloqueado", IF( Tabela_Movimentacao_Geral[[#This Row],[Tipo Fluxo]]="Entrada", Tabela_Movimentacao_Geral[[#This Row],[Data]] + _xlfn.XLOOKUP(Tabela_Movimentacao_Geral[[#This Row],[ID Entidade]],Tabela_Fornecedores[ID_Fornecedor],Tabela_Fornecedores[Lead_Time]), "N/A" ), Tabela_Movimentacao_Geral[[#This Row],[Previsão de Entrega]] ) -> 45664
A4: T0003 | B4: 45660 | C4: Saida | D4: CLI001 | E4: =IF(Tabela_Movimentacao_Geral[[#This Row],[Tipo Fluxo]]="Saida",_xlfn.XLOOKUP(Tabela_Movimentacao_Geral[[#This Row],[ID Entidade]], Tabela_Clientes[ID_Cliente],Tabela_Clientes[Nome_Cliente],"Cliente não encontrado"),_xlfn.XLOOKUP(Tabela_Movimentacao_Geral[[#This Row],[ID Entidade]], Tabela_Fornecedores[ID_Fornecedor], Tabela_Fornecedores[Nome_Fantasia], "Fornecedor não encontrado")) -> Industrias Alpha | F4: PROD005 | G4: =_xlfn.XLOOKUP(Tabela_Movimentacao_Geral[[#This Row],[ID Produto]], Tabela_Produtos[ID_Produto],Tabela_Produtos[Descricao_Produto],"Produto não encontrado") -> Notebook i5 8GB 256GB SSD | H4: 1 | I4: =_xlfn.XLOOKUP(Tabela_Movimentacao_Geral[[#This Row],[ID Produto]], Tabela_Produtos[ID_Produto],Tabela_Produtos[Preco_Unitario_Venda]) -> 3500 | J4: =Tabela_Movimentacao_Geral[[#This Row],[Quantidade]] * Tabela_Movimentacao_Geral[[#This Row],[Valor Unitário]] -> 3500 | K4: Atrasado | L4: Entregue | M4: =IF( $O$7="Desbloqueado", IF( Tabela_Movimentacao_Geral[[#This Row],[Tipo Fluxo]]="Entrada", Tabela_Movimentacao_Geral[[#This Row],[Data]] + _xlfn.XLOOKUP(Tabela_Movimentacao_Geral[[#This Row],[ID Entidade]],Tabela_Fornecedores[ID_Fornecedor],Tabela_Fornecedores[Lead_Time]), "N/A" ), Tabela_Movimentacao_Geral[[#This Row],[Previsão de Entrega]] ) -> N/A
A5: T0004 | B5: 45661 | C5: Saida | D5: CLI020 | E5: =IF(Tabela_Movimentacao_Geral[[#This Row],[Tipo Fluxo]]="Saida",_xlfn.XLOOKUP(Tabela_Movimentacao_Geral[[#This Row],[ID Entidade]], Tabela_Clientes[ID_Cliente],Tabela_Clientes[Nome_Cliente],"Cliente não encontrado"),_xlfn.XLOOKUP(Tabela_Movimentacao_Geral[[#This Row],[ID Entidade]], Tabela_Fornecedores[ID_Fornecedor], Tabela_Fornecedores[Nome_Fantasia], "Fornecedor não encontrado")) -> Oficina Mecanica | F5: PROD003 | G5: =_xlfn.XLOOKUP(Tabela_Movimentacao_Geral[[#This Row],[ID Produto]], Tabela_Produtos[ID_Produto],Tabela_Produtos[Descricao_Produto],"Produto não encontrado") -> Mouse Sem Fio Optico | H5: 5 | I5: =_xlfn.XLOOKUP(Tabela_Movimentacao_Geral[[#This Row],[ID Produto]], Tabela_Produtos[ID_Produto],Tabela_Produtos[Preco_Unitario_Venda]) -> 120 | J5: =Tabela_Movimentacao_Geral[[#This Row],[Quantidade]] * Tabela_Movimentacao_Geral[[#This Row],[Valor Unitário]] -> 600 | K5: Pago | L5: Em Rota | M5: =IF( $O$7="Desbloqueado", IF( Tabela_Movimentacao_Geral[[#This Row],[Tipo Fluxo]]="Entrada", Tabela_Movimentacao_Geral[[#This Row],[Data]] + _xlfn.XLOOKUP(Tabela_Movimentacao_Geral[[#This Row],[ID Entidade]],Tabela_Fornecedores[ID_Fornecedor],Tabela_Fornecedores[Lead_Time]), "N/A" ), Tabela_Movimentacao_Geral[[#This Row],[Previsão de Entrega]] ) -> N/A
A6: T0005 | B6: 45662 | C6: Entrada | D6: FORN008 | E6: =IF(Tabela_Movimentacao_Geral[[#This Row],[Tipo Fluxo]]="Saida",_xlfn.XLOOKUP(Tabela_Movimentacao_Geral[[#This Row],[ID Entidade]], Tabela_Clientes[ID_Cliente],Tabela_Clientes[Nome_Cliente],"Cliente não encontrado"),_xlfn.XLOOKUP(Tabela_Movimentacao_Geral[[#This Row],[ID Entidade]], Tabela_Fornecedores[ID_Fornecedor], Tabela_Fornecedores[Nome_Fantasia], "Fornecedor não encontrado")) -> Global Chips | F6: PROD010 | G6: =_xlfn.XLOOKUP(Tabela_Movimentacao_Geral[[#This Row],[ID Produto]], Tabela_Produtos[ID_Produto],Tabela_Produtos[Descricao_Produto],"Produto não encontrado") -> SSD 480GB SATA3 | H6: 50 | I6: =_xlfn.XLOOKUP(Tabela_Movimentacao_Geral[[#This Row],[ID Produto]], Tabela_Produtos[ID_Produto],Tabela_Produtos[Preco_Unitario_Venda]) -> 320 | J6: =Tabela_Movimentacao_Geral[[#This Row],[Quantidade]] * Tabela_Movimentacao_Geral[[#This Row],[Valor Unitário]] -> 16000 | K6: Pago | L6: Entregue | M6: =IF( $O$7="Desbloqueado", IF( Tabela_Movimentacao_Geral[[#This Row],[Tipo Fluxo]]="Entrada", Tabela_Movimentacao_Geral[[#This Row],[Data]] + _xlfn.XLOOKUP(Tabela_Movimentacao_Geral[[#This Row],[ID Entidade]],Tabela_Fornecedores[ID_Fornecedor],Tabela_Fornecedores[Lead_Time]), "N/A" ), Tabela_Movimentacao_Geral[[#This Row],[Previsão de Entrega]] ) -> 45677
A7: T0006 | B7: 45663 | C7: Saida | D7: CLI010 | E7: =IF(Tabela_Movimentacao_Geral[[#This Row],[Tipo Fluxo]]="Saida",_xlfn.XLOOKUP(Tabela_Movimentacao_Geral[[#This Row],[ID Entidade]], Tabela_Clientes[ID_Cliente],Tabela_Clientes[Nome_Cliente],"Cliente não encontrado"),_xlfn.XLOOKUP(Tabela_Movimentacao_Geral[[#This Row],[ID Entidade]], Tabela_Fornecedores[ID_Fornecedor], Tabela_Fornecedores[Nome_Fantasia], "Fornecedor não encontrado")) -> Hotel Estrela | F7: PROD042 | G7: =_xlfn.XLOOKUP(Tabela_Movimentacao_Geral[[#This Row],[ID Produto]], Tabela_Produtos[ID_Produto],Tabela_Produtos[Descricao_Produto],"Produto não encontrado") -> Docking Station Universal | H7: 1 | I7: =_xlfn.XLOOKUP(Tabela_Movimentacao_Geral[[#This Row],[ID Produto]], Tabela_Produtos[ID_Produto],Tabela_Produtos[Preco_Unitario_Venda]) -> 890 | J7: =Tabela_Movimentacao_Geral[[#This Row],[Quantidade]] * Tabela_Movimentacao_Geral[[#This Row],[Valor Unitário]] -> 890 | K7: Pago | L7: Entregue | M7: =IF( $O$7="Desbloqueado", IF( Tabela_Movimentacao_Geral[[#This Row],[Tipo Fluxo]]="Entrada", Tabela_Movimentacao_Geral[[#This Row],[Data]] + _xlfn.XLOOKUP(Tabela_Movimentacao_Geral[[#This Row],[ID Entidade]],Tabela_Fornecedores[ID_Fornecedor],Tabela_Fornecedores[Lead_Time]), "N/A" ), Tabela_Movimentacao_Geral[[#This Row],[Previsão de Entrega]] ) -> N/A | O7: Bloqueado
A8: T0007 | B8: 45664 | C8: Entrada | D8: FORN015 | E8: =IF(Tabela_Movimentacao_Geral[[#This Row],[Tipo Fluxo]]="Saida",_xlfn.XLOOKUP(Tabela_Movimentacao_Geral[[#This Row],[ID Entidade]], Tabela_Clientes[ID_Cliente],Tabela_Clientes[Nome_Cliente],"Cliente não encontrado"),_xlfn.XLOOKUP(Tabela_Movimentacao_Geral[[#This Row],[ID Entidade]], Tabela_Fornecedores[ID_Fornecedor], Tabela_Fornecedores[Nome_Fantasia], "Fornecedor não encontrado")) -> Print Smart | F8: PROD051 | G8: =_xlfn.XLOOKUP(Tabela_Movimentacao_Geral[[#This Row],[ID Produto]], Tabela_Produtos[ID_Produto],Tabela_Produtos[Descricao_Produto],"Produto não encontrado") -> Papel A4 Report 500fls | H8: 100 | I8: =_xlfn.XLOOKUP(Tabela_Movimentacao_Geral[[#This Row],[ID Produto]], Tabela_Produtos[ID_Produto],Tabela_Produtos[Preco_Unitario_Venda]) -> 28 | J8: =Tabela_Movimentacao_Geral[[#This Row],[Quantidade]] * Tabela_Movimentacao_Geral[[#This Row],[Valor Unitário]] -> 2800 | K8: Pendente | L8: Aguardando | M8: =IF( $O$7="Desbloqueado", IF( Tabela_Movimentacao_Geral[[#This Row],[Tipo Fluxo]]="Entrada", Tabela_Movimentacao_Geral[[#This Row],[Data]] + _xlfn.XLOOKUP(Tabela_Movimentacao_Geral[[#This Row],[ID Entidade]],Tabela_Fornecedores[ID_Fornecedor],Tabela_Fornecedores[Lead_Time]), "N/A" ), Tabela_Movimentacao_Geral[[#This Row],[Previsão de Entrega]] ) -> 45667
A9: T0008 | B9: 45665 | C9: Saida | D9: CLI003 | E9: =IF(Tabela_Movimentacao_Geral[[#This Row],[Tipo Fluxo]]="Saida",_xlfn.XLOOKUP(Tabela_Movimentacao_Geral[[#This Row],[ID Entidade]], Tabela_Clientes[ID_Cliente],Tabela_Clientes[Nome_Cliente],"Cliente não encontrado"),_xlfn.XLOOKUP(Tabela_Movimentacao_Geral[[#This Row],[ID Entidade]], Tabela_Fornecedores[ID_Fornecedor], Tabela_Fornecedores[Nome_Fantasia], "Fornecedor não encontrado")) -> Hospital Vida | F9: PROD106 | G9: =_xlfn.XLOOKUP(Tabela_Movimentacao_Geral[[#This Row],[ID Produto]], Tabela_Produtos[ID_Produto],Tabela_Produtos[Descricao_Produto],"Produto não encontrado") -> MacBook Air M2 13p | H9: 1 | I9: =_xlfn.XLOOKUP(Tabela_Movimentacao_Geral[[#This Row],[ID Produto]], Tabela_Produtos[ID_Produto],Tabela_Produtos[Preco_Unitario_Venda]) -> 9500 | J9: =Tabela_Movimentacao_Geral[[#This Row],[Quantidade]] * Tabela_Movimentacao_Geral[[#This Row],[Valor Unitário]] -> 9500 | K9: Pago | L9: Em Rota | M9: =IF( $O$7="Desbloqueado", IF( Tabela_Movimentacao_Geral[[#This Row],[Tipo Fluxo]]="Entrada", Tabela_Movimentacao_Geral[[#This Row],[Data]] + _xlfn.XLOOKUP(Tabela_Movimentacao_Geral[[#This Row],[ID Entidade]],Tabela_Fornecedores[ID_Fornecedor],Tabela_Fornecedores[Lead_Time]), "N/A" ), Tabela_Movimentacao_Geral[[#This Row],[Previsão de Entrega]] ) -> N/A | O9: Manter Bloqueado para atualizar o Dashbard!
A10: T0009 | B10: 45666 | C10: Saida | D10: CLI015 | E10: =IF(Tabela_Movimentacao_Geral[[#This Row],[Tipo Fluxo]]="Saida",_xlfn.XLOOKUP(Tabela_Movimentacao_Geral[[#This Row],[ID Entidade]], Tabela_Clientes[ID_Cliente],Tabela_Clientes[Nome_Cliente],"Cliente não encontrado"),_xlfn.XLOOKUP(Tabela_Movimentacao_Geral[[#This Row],[ID Entidade]], Tabela_Fornecedores[ID_Fornecedor], Tabela_Fornecedores[Nome_Fantasia], "Fornecedor não encontrado")) -> Pet Shop Amigo | F10: PROD012 | G10: =_xlfn.XLOOKUP(Tabela_Movimentacao_Geral[[#This Row],[ID Produto]], Tabela_Produtos[ID_Produto],Tabela_Produtos[Descricao_Produto],"Produto não encontrado") -> Webcam 1080p Business | H10: 3 | I10: =_xlfn.XLOOKUP(Tabela_Movimentacao_Geral[[#This Row],[ID Produto]], Tabela_Produtos[ID_Produto],Tabela_Produtos[Preco_Unitario_Venda]) -> 450 | J10: =Tabela_Movimentacao_Geral[[#This Row],[Quantidade]] * Tabela_Movimentacao_Geral[[#This Row],[Valor Unitário]] -> 1350 | K10: Atrasado | L10: Aguardando | M10: =IF( $O$7="Desbloqueado", IF( Tabela_Movimentacao_Geral[[#This Row],[Tipo Fluxo]]="Entrada", Tabela_Movimentacao_Geral[[#This Row],[Data]] + _xlfn.XLOOKUP(Tabela_Movimentacao_Geral[[#This Row],[ID Entidade]],Tabela_Fornecedores[ID_Fornecedor],Tabela_Fornecedores[Lead_Time]), "N/A" ), Tabela_Movimentacao_Geral[[#This Row],[Previsão de Entrega]] ) -> N/A
A11: T0010 | B11: 45667 | C11: Entrada | D11: FORN020 | E11: =IF(Tabela_Movimentacao_Geral[[#This Row],[Tipo Fluxo]]="Saida",_xlfn.XLOOKUP(Tabela_Movimentacao_Geral[[#This Row],[ID Entidade]], Tabela_Clientes[ID_Cliente],Tabela_Clientes[Nome_Cliente],"Cliente não encontrado"),_xlfn.XLOOKUP(Tabela_Movimentacao_Geral[[#This Row],[ID Entidade]], Tabela_Fornecedores[ID_Fornecedor], Tabela_Fornecedores[Nome_Fantasia], "Fornecedor não encontrado")) -> AI Systems | F11: PROD121 | G11: =_xlfn.XLOOKUP(Tabela_Movimentacao_Geral[[#This Row],[ID Produto]], Tabela_Produtos[ID_Produto],Tabela_Produtos[Descricao_Produto],"Produto não encontrado") -> Licenca SQL Server Standard | H11: 1 | I11: =_xlfn.XLOOKUP(Tabela_Movimentacao_Geral[[#This Row],[ID Produto]], Tabela_Produtos[ID_Produto],Tabela_Produtos[Preco_Unitario_Venda]) -> 15000 | J11: =Tabela_Movimentacao_Geral[[#This Row],[Quantidade]] * Tabela_Movimentacao_Geral[[#This Row],[Valor Unitário]] -> 15000 | K11: Pago | L11: Entregue | M11: =IF( $O$7="Desbloqueado", IF( Tabela_Movimentacao_Geral[[#This Row],[Tipo Fluxo]]="Entrada", Tabela_Movimentacao_Geral[[#This Row],[Data]] + _xlfn.XLOOKUP(Tabela_Movimentacao_Geral[[#This Row],[ID Entidade]],Tabela_Fornecedores[ID_Fornecedor],Tabela_Fornecedores[Lead_Time]), "N/A" ), Tabela_Movimentacao_Geral[[#This Row],[Previsão de Entrega]] ) -> 45668
A12: T0011 | B12: 45668 | C12: Saida | D12: CLI007 | E12: =IF(Tabela_Movimentacao_Geral[[#This Row],[Tipo Fluxo]]="Saida",_xlfn.XLOOKUP(Tabela_Movimentacao_Geral[[#This Row],[ID Entidade]], Tabela_Clientes[ID_Cliente],Tabela_Clientes[Nome_Cliente],"Cliente não encontrado"),_xlfn.XLOOKUP(Tabela_Movimentacao_Geral[[#This Row],[ID Entidade]], Tabela_Fornecedores[ID_Fornecedor], Tabela_Fornecedores[Nome_Fantasia], "Fornecedor não encontrado")) -> Tecno Logica | F12: PROD002 | G12: =_xlfn.XLOOKUP(Tabela_Movimentacao_Geral[[#This Row],[ID Produto]], Tabela_Produtos[ID_Produto],Tabela_Produtos[Descricao_Produto],"Produto não encontrado") -> Teclado Mecanico RGB | H12: 4 | I12: =_xlfn.XLOOKUP(Tabela_Movimentacao_Geral[[#This Row],[ID Produto]], Tabela_Produtos[ID_Produto],Tabela_Produtos[Preco_Unitario_Venda]) -> 350 | J12: =Tabela_Movimentacao_Geral[[#This Row],[Quantidade]] * Tabela_Movimentacao_Geral[[#This Row],[Valor Unitário]] -> 1400 | K12: Pendente | L12: Em Rota | M12: =IF( $O$7="Desbloqueado", IF( Tabela_Movimentacao_Geral[[#This Row],[Tipo Fluxo]]="Entrada", Tabela_Movimentacao_Geral[[#This Row],[Data]] + _xlfn.XLOOKUP(Tabela_Movimentacao_Geral[[#This Row],[ID Entidade]],Tabela_Fornecedores[ID_Fornecedor],Tabela_Fornecedores[Lead_Time]), "N/A" ), Tabela_Movimentacao_Geral[[#This Row],[Previsão de Entrega]] ) -> N/A
A13: T0012 | B13: 45669 | C13: Saida | D13: CLI009 | E13: =IF(Tabela_Movimentacao_Geral[[#This Row],[Tipo Fluxo]]="Saida",_xlfn.XLOOKUP(Tabela_Movimentacao_Geral[[#This Row],[ID Entidade]], Tabela_Clientes[ID_Cliente],Tabela_Clientes[Nome_Cliente],"Cliente não encontrado"),_xlfn.XLOOKUP(Tabela_Movimentacao_Geral[[#This Row],[ID Entidade]], Tabela_Fornecedores[ID_Fornecedor], Tabela_Fornecedores[Nome_Fantasia], "Fornecedor não encontrado")) -> Farma Plus | F13: PROD085 | G13: =_xlfn.XLOOKUP(Tabela_Movimentacao_Geral[[#This Row],[ID Produto]], Tabela_Produtos[ID_Produto],Tabela_Produtos[Descricao_Produto],"Produto não encontrado") -> Cabo Optico Patch Cord 3m | H13: 20 | I13: =_xlfn.XLOOKUP(Tabela_Movimentacao_Geral[[#This Row],[ID Produto]], Tabela_Produtos[ID_Produto],Tabela_Produtos[Preco_Unitario_Venda]) -> 85 | J13: =Tabela_Movimentacao_Geral[[#This Row],[Quantidade]] * Tabela_Movimentacao_Geral[[#This Row],[Valor Unitário]] -> 1700 | K13: Pago | L13: Entregue | M13: =IF( $O$7="Desbloqueado", IF( Tabela_Movimentacao_Geral[[#This Row],[Tipo Fluxo]]="Entrada", Tabela_Movimentacao_Geral[[#This Row],[Data]] + _xlfn.XLOOKUP(Tabela_Movimentacao_Geral[[#This Row],[ID Entidade]],Tabela_Fornecedores[ID_Fornecedor],Tabela_Fornecedores[Lead_Time]), "N/A" ), Tabela_Movimentacao_Geral[[#This Row],[Previsão de Entrega]] ) -> N/A
A14: T0013 | B14: 45670 | C14: Entrada | D14: FORN002 | E14: =IF(Tabela_Movimentacao_Geral[[#This Row],[Tipo Fluxo]]="Saida",_xlfn.XLOOKUP(Tabela_Movimentacao_Geral[[#This Row],[ID Entidade]], Tabela_Clientes[ID_Cliente],Tabela_Clientes[Nome_Cliente],"Cliente não encontrado"),_xlfn.XLOOKUP(Tabela_Movimentacao_Geral[[#This Row],[ID Entidade]], Tabela_Fornecedores[ID_Fornecedor], Tabela_Fornecedores[Nome_Fantasia], "Fornecedor não encontrado")) -> SoftPrime Licencas | F14: PROD022 | G14: =_xlfn.XLOOKUP(Tabela_Movimentacao_Geral[[#This Row],[ID Produto]], Tabela_Produtos[ID_Produto],Tabela_Produtos[Descricao_Produto],"Produto não encontrado") -> Licenca Windows 11 Pro | H14: 10 | I14: =_xlfn.XLOOKUP(Tabela_Movimentacao_Geral[[#This Row],[ID Produto]], Tabela_Produtos[ID_Produto],Tabela_Produtos[Preco_Unitario_Venda]) -> 980 | J14: =Tabela_Movimentacao_Geral[[#This Row],[Quantidade]] * Tabela_Movimentacao_Geral[[#This Row],[Valor Unitário]] -> 9800 | K14: Pago | L14: Entregue | M14: =IF( $O$7="Desbloqueado", IF( Tabela_Movimentacao_Geral[[#This Row],[Tipo Fluxo]]="Entrada", Tabela_Movimentacao_Geral[[#This Row],[Data]] + _xlfn.XLOOKUP(Tabela_Movimentacao_Geral[[#This Row],[ID Entidade]],Tabela_Fornecedores[ID_Fornecedor],Tabela_Fornecedores[Lead_Time]), "N/A" ), Tabela_Movimentacao_Geral[[#This Row],[Previsão de Entrega]] ) -> 45671
A15: T0014 | B15: 45671 | C15: Saida | D15: CLI018 | E15: =IF(Tabela_Movimentacao_Geral[[#This Row],[Tipo Fluxo]]="Saida",_xlfn.XLOOKUP(Tabela_Movimentacao_Geral[[#This Row],[ID Entidade]], Tabela_Clientes[ID_Cliente],Tabela_Clientes[Nome_Cliente],"Cliente não encontrado"),_xlfn.XLOOKUP(Tabela_Movimentacao_Geral[[#This Row],[ID Entidade]], Tabela_Fornecedores[ID_Fornecedor], Tabela_Fornecedores[Nome_Fantasia], "Fornecedor não encontrado")) -> Clinica Sorriso | F15: PROD113 | G15: =_xlfn.XLOOKUP(Tabela_Movimentacao_Geral[[#This Row],[ID Produto]], Tabela_Produtos[ID_Produto],Tabela_Produtos[Descricao_Produto],"Produto não encontrado") -> Headphone Bluetooth NoiseC | H15: 2 | I15: =_xlfn.XLOOKUP(Tabela_Movimentacao_Geral[[#This Row],[ID Produto]], Tabela_Produtos[ID_Produto],Tabela_Produtos[Preco_Unitario_Venda]) -> 950 | J15: =Tabela_Movimentacao_Geral[[#This Row],[Quantidade]] * Tabela_Movimentacao_Geral[[#This Row],[Valor Unitário]] -> 1900 | K15: Pendente | L15: Em Rota | M15: =IF( $O$7="Desbloqueado", IF( Tabela_Movimentacao_Geral[[#This Row],[Tipo Fluxo]]="Entrada", Tabela_Movimentacao_Geral[[#This Row],[Data]] + _xlfn.XLOOKUP(Tabela_Movimentacao_Geral[[#This Row],[ID Entidade]],Tabela_Fornecedores[ID_Fornecedor],Tabela_Fornecedores[Lead_Time]), "N/A" ), Tabela_Movimentacao_Geral[[#This Row],[Previsão de Entrega]] ) -> N/A
A16: T0015 | B16: 45672 | C16: Saida | D16: CLI002 | E16: =IF(Tabela_Movimentacao_Geral[[#This Row],[Tipo Fluxo]]="Saida",_xlfn.XLOOKUP(Tabela_Movimentacao_Geral[[#This Row],[ID Entidade]], Tabela_Clientes[ID_Cliente],Tabela_Clientes[Nome_Cliente],"Cliente não encontrado"),_xlfn.XLOOKUP(Tabela_Movimentacao_Geral[[#This Row],[ID Entidade]], Tabela_Fornecedores[ID_Fornecedor], Tabela_Fornecedores[Nome_Fantasia], "Fornecedor não encontrado")) -> Varejo Total | F16: PROD033 | G16: =_xlfn.XLOOKUP(Tabela_Movimentacao_Geral[[#This Row],[ID Produto]], Tabela_Produtos[ID_Produto],Tabela_Produtos[Descricao_Produto],"Produto não encontrado") -> Pendrive 64GB USB 3.1 | H16: 15 | I16: =_xlfn.XLOOKUP(Tabela_Movimentacao_Geral[[#This Row],[ID Produto]], Tabela_Produtos[ID_Produto],Tabela_Produtos[Preco_Unitario_Venda]) -> 65 | J16: =Tabela_Movimentacao_Geral[[#This Row],[Quantidade]] * Tabela_Movimentacao_Geral[[#This Row],[Valor Unitário]] -> 975 | K16: Pago | L16: Entregue | M16: =IF( $O$7="Desbloqueado", IF( Tabela_Movimentacao_Geral[[#This Row],[Tipo Fluxo]]="Entrada", Tabela_Movimentacao_Geral[[#This Row],[Data]] + _xlfn.XLOOKUP(Tabela_Movimentacao_Geral[[#This Row],[ID Entidade]],Tabela_Fornecedores[ID_Fornecedor],Tabela_Fornecedores[Lead_Time]), "N/A" ), Tabela_Movimentacao_Geral[[#This Row],[Previsão de Entrega]] ) -> N/A
A17: T0016 | B17: 45673 | C17: Entrada | D17: FORN011 | E17: =IF(Tabela_Movimentacao_Geral[[#This Row],[Tipo Fluxo]]="Saida",_xlfn.XLOOKUP(Tabela_Movimentacao_Geral[[#This Row],[ID Entidade]], Tabela_Clientes[ID_Cliente],Tabela_Clientes[Nome_Cliente],"Cliente não encontrado"),_xlfn.XLOOKUP(Tabela_Movimentacao_Geral[[#This Row],[ID Entidade]], Tabela_Fornecedores[ID_Fornecedor], Tabela_Fornecedores[Nome_Fantasia], "Fornecedor não encontrado")) -> Energy Solution | F17: PROD131 | G17: =_xlfn.XLOOKUP(Tabela_Movimentacao_Geral[[#This Row],[ID Produto]], Tabela_Produtos[ID_Produto],Tabela_Produtos[Descricao_Produto],"Produto não encontrado") -> Bateria Nobreak 12V 7Ah | H17: 5 | I17: =_xlfn.XLOOKUP(Tabela_Movimentacao_Geral[[#This Row],[ID Produto]], Tabela_Produtos[ID_Produto],Tabela_Produtos[Preco_Unitario_Venda]) -> 145 | J17: =Tabela_Movimentacao_Geral[[#This Row],[Quantidade]] * Tabela_Movimentacao_Geral[[#This Row],[Valor Unitário]] -> 725 | K17: Atrasado | L17: Aguardando | M17: =IF( $O$7="Desbloqueado", IF( Tabela_Movimentacao_Geral[[#This Row],[Tipo Fluxo]]="Entrada", Tabela_Movimentacao_Geral[[#This Row],[Data]] + _xlfn.XLOOKUP(Tabela_Movimentacao_Geral[[#This Row],[ID Entidade]],Tabela_Fornecedores[ID_Fornecedor],Tabela_Fornecedores[Lead_Time]), "N/A" ), Tabela_Movimentacao_Geral[[#This Row],[Previsão de Entrega]] ) -> 45677 | O17: Ctrl + Alt + F5 (Atualiza todas as conexões e tabelas do arquivo de uma vez só).
A18: T0017 | B18: 45674 | C18: Saida | D18: CLI004 | E18: =IF(Tabela_Movimentacao_Geral[[#This Row],[Tipo Fluxo]]="Saida",_xlfn.XLOOKUP(Tabela_Movimentacao_Geral[[#This Row],[ID Entidade]], Tabela_Clientes[ID_Cliente],Tabela_Clientes[Nome_Cliente],"Cliente não encontrado"),_xlfn.XLOOKUP(Tabela_Movimentacao_Geral[[#This Row],[ID Entidade]], Tabela_Fornecedores[ID_Fornecedor], Tabela_Fornecedores[Nome_Fantasia], "Fornecedor não encontrado")) -> Escola Saber | F18: PROD009 | G18: =_xlfn.XLOOKUP(Tabela_Movimentacao_Geral[[#This Row],[ID Produto]], Tabela_Produtos[ID_Produto],Tabela_Produtos[Descricao_Produto],"Produto não encontrado") -> Cabo HDMI 2.0 2m | H18: 30 | I18: =_xlfn.XLOOKUP(Tabela_Movimentacao_Geral[[#This Row],[ID Produto]], Tabela_Produtos[ID_Produto],Tabela_Produtos[Preco_Unitario_Venda]) -> 45 | J18: =Tabela_Movimentacao_Geral[[#This Row],[Quantidade]] * Tabela_Movimentacao_Geral[[#This Row],[Valor Unitário]] -> 1350 | K18: Pago | L18: Entregue | M18: =IF( $O$7="Desbloqueado", IF( Tabela_Movimentacao_Geral[[#This Row],[Tipo Fluxo]]="Entrada", Tabela_Movimentacao_Geral[[#This Row],[Data]] + _xlfn.XLOOKUP(Tabela_Movimentacao_Geral[[#This Row],[ID Entidade]],Tabela_Fornecedores[ID_Fornecedor],Tabela_Fornecedores[Lead_Time]), "N/A" ), Tabela_Movimentacao_Geral[[#This Row],[Previsão de Entrega]] ) -> N/A
A19: T0018 | B19: 45675 | C19: Entrada | D19: FORN005 | E19: =IF(Tabela_Movimentacao_Geral[[#This Row],[Tipo Fluxo]]="Saida",_xlfn.XLOOKUP(Tabela_Movimentacao_Geral[[#This Row],[ID Entidade]], Tabela_Clientes[ID_Cliente],Tabela_Clientes[Nome_Cliente],"Cliente não encontrado"),_xlfn.XLOOKUP(Tabela_Movimentacao_Geral[[#This Row],[ID Entidade]], Tabela_Fornecedores[ID_Fornecedor], Tabela_Fornecedores[Nome_Fantasia], "Fornecedor não encontrado")) -> CloudNexus Data | F19: PROD189 | G19: =_xlfn.XLOOKUP(Tabela_Movimentacao_Geral[[#This Row],[ID Produto]], Tabela_Produtos[ID_Produto],Tabela_Produtos[Descricao_Produto],"Produto não encontrado") -> Switch Core Layer 3 | H19: 1 | I19: =_xlfn.XLOOKUP(Tabela_Movimentacao_Geral[[#This Row],[ID Produto]], Tabela_Produtos[ID_Produto],Tabela_Produtos[Preco_Unitario_Venda]) -> 22000 | J19: =Tabela_Movimentacao_Geral[[#This Row],[Quantidade]] * Tabela_Movimentacao_Geral[[#This Row],[Valor Unitário]] -> 22000 | K19: Pago | L19: Entregue | M19: =IF( $O$7="Desbloqueado", IF( Tabela_Movimentacao_Geral[[#This Row],[Tipo Fluxo]]="Entrada", Tabela_Movimentacao_Geral[[#This Row],[Data]] + _xlfn.XLOOKUP(Tabela_Movimentacao_Geral[[#This Row],[ID Entidade]],Tabela_Fornecedores[ID_Fornecedor],Tabela_Fornecedores[Lead_Time]), "N/A" ), Tabela_Movimentacao_Geral[[#This Row],[Previsão de Entrega]] ) -> 45676
A20: T0019 | B20: 45676 | C20: Saida | D20: CLI012 | E20: =IF(Tabela_Movimentacao_Geral[[#This Row],[Tipo Fluxo]]="Saida",_xlfn.XLOOKUP(Tabela_Movimentacao_Geral[[#This Row],[ID Entidade]], Tabela_Clientes[ID_Cliente],Tabela_Clientes[Nome_Cliente],"Cliente não encontrado"),_xlfn.XLOOKUP(Tabela_Movimentacao_Geral[[#This Row],[ID Entidade]], Tabela_Fornecedores[ID_Fornecedor], Tabela_Fornecedores[Nome_Fantasia], "Fornecedor não encontrado")) -> Padaria Real | F20: PROD007 | G20: =_xlfn.XLOOKUP(Tabela_Movimentacao_Geral[[#This Row],[ID Produto]], Tabela_Produtos[ID_Produto],Tabela_Produtos[Descricao_Produto],"Produto não encontrado") -> Impressora Laser Color | H20: 1 | I20: =_xlfn.XLOOKUP(Tabela_Movimentacao_Geral[[#This Row],[ID Produto]], Tabela_Produtos[ID_Produto],Tabela_Produtos[Preco_Unitario_Venda]) -> 1800 | J20: =Tabela_Movimentacao_Geral[[#This Row],[Quantidade]] * Tabela_Movimentacao_Geral[[#This Row],[Valor Unitário]] -> 1800 | K20: Pago | L20: Em Rota | M20: =IF( $O$7="Desbloqueado", IF( Tabela_Movimentacao_Geral[[#This Row],[Tipo Fluxo]]="Entrada", Tabela_Movimentacao_Geral[[#This Row],[Data]] + _xlfn.XLOOKUP(Tabela_Movimentacao_Geral[[#This Row],[ID Entidade]],Tabela_Fornecedores[ID_Fornecedor],Tabela_Fornecedores[Lead_Time]), "N/A" ), Tabela_Movimentacao_Geral[[#This Row],[Previsão de Entrega]] ) -> N/A
A21: T0020 | B21: 45677 | C21: Saida | D21: CLI008 | E21: =IF(Tabela_Movimentacao_Geral[[#This Row],[Tipo Fluxo]]="Saida",_xlfn.XLOOKUP(Tabela_Movimentacao_Geral[[#This Row],[ID Entidade]], Tabela_Clientes[ID_Cliente],Tabela_Clientes[Nome_Cliente],"Cliente não encontrado"),_xlfn.XLOOKUP(Tabela_Movimentacao_Geral[[#This Row],[ID Entidade]], Tabela_Fornecedores[ID_Fornecedor], Tabela_Fornecedores[Nome_Fantasia], "Fornecedor não encontrado")) -> Supermercado Sol | F21: PROD018 | G21: =_xlfn.XLOOKUP(Tabela_Movimentacao_Geral[[#This Row],[ID Produto]], Tabela_Produtos[ID_Produto],Tabela_Produtos[Descricao_Produto],"Produto não encontrado") -> HD Externo 1TB | H21: 5 | I21: =_xlfn.XLOOKUP(Tabela_Movimentacao_Geral[[#This Row],[ID Produto]], Tabela_Produtos[ID_Produto],Tabela_Produtos[Preco_Unitario_Venda]) -> 380 | J21: =Tabela_Movimentacao_Geral[[#This Row],[Quantidade]] * Tabela_Movimentacao_Geral[[#This Row],[Valor Unitário]] -> 1900 | K21: Pendente | L21: Entregue | M21: =IF( $O$7="Desbloqueado", IF( Tabela_Movimentacao_Geral[[#This Row],[Tipo Fluxo]]="Entrada", Tabela_Movimentacao_Geral[[#This Row],[Data]] + _xlfn.XLOOKUP(Tabela_Movimentacao_Geral[[#This Row],[ID Entidade]],Tabela_Fornecedores[ID_Fornecedor],Tabela_Fornecedores[Lead_Time]), "N/A" ), Tabela_Movimentacao_Geral[[#This Row],[Previsão de Entrega]] ) -> N/A
A22: ="T"&TEXT(ROW(A22)-1,"0000") -> T0021 | B22: 45677 | C22: {=IF($O$7="Desbloqueado", _xlfn.LET( _xlpm.saldo_atual, SUM(($C$2:$C21="Entrada")*($F$2:$F21=Tabela_Movimentacao_Geral[[#This Row],[ID Produto]])*($H$2:$H21) - ($C$2:$C21="Saida")*($F$2:$F21=Tabela_Movimentacao_Geral[[#This Row],[ID Produto]])*($H$2:$H21)), IF(_xlpm.saldo_atual > 0, IF(RANDBETWEEN(0,10)>3,"Saida","Entrada"), "Entrada") ), Tabela_Movimentacao_Geral[[#This Row],[Tipo Fluxo]] )} -> Entrada | D22: =IF( $O$7="Desbloqueado", IF( Tabela_Movimentacao_Geral[[#This Row],[Tipo Fluxo]]="Saida", "CLI"&TEXT(RANDBETWEEN(1,20),"000"), "FORN"&TEXT(RANDBETWEEN(1,20),"000") ), Tabela_Movimentacao_Geral[[#This Row],[ID Entidade]] ) -> FORN004 | E22: =IF(Tabela_Movimentacao_Geral[[#This Row],[Tipo Fluxo]]="Saida",_xlfn.XLOOKUP(Tabela_Movimentacao_Geral[[#This Row],[ID Entidade]], Tabela_Clientes[ID_Cliente],Tabela_Clientes[Nome_Cliente],"Cliente não encontrado"),_xlfn.XLOOKUP(Tabela_Movimentacao_Geral[[#This Row],[ID Entidade]], Tabela_Fornecedores[ID_Fornecedor], Tabela_Fornecedores[Nome_Fantasia], "Fornecedor não encontrado")) -> LogiBrasil Transportes | F22: =IF( $O$7="Desbloqueado", "PROD"&TEXT(RANDBETWEEN(1,200),"000"), Tabela_Movimentacao_Geral[[#This Row],[ID Produto]] ) -> PROD195 | G22: =_xlfn.XLOOKUP(Tabela_Movimentacao_Geral[[#This Row],[ID Produto]], Tabela_Produtos[ID_Produto],Tabela_Produtos[Descricao_Produto],"Produto não encontrado") -> Terminador Optico | H22: {=IF( $O$7="Desbloqueado", _xlfn.LET( _xlpm.saldo_atual, SUM(($C$2:$C21="Entrada")*($F$2:$F21=Tabela_Movimentacao_Geral[[#This Row],[ID Produto]])*($H$2:$H21) - ($C$2:$C21="Saida")*($F$2:$F21=Tabela_Movimentacao_Geral[[#This Row],[ID Produto]])*($H$2:$H21)), _xlpm.estoque_minimo, _xlfn.XLOOKUP(Tabela_Movimentacao_Geral[[#This Row],[ID Produto]], Tabela_Produtos[ID_Produto], Tabela_Produtos[Estoque_Minimo], 0), IF( _xlpm.saldo_atual > _xlpm.estoque_minimo, IF( Tabela_Movimentacao_Geral[[#This Row],[Tipo Fluxo]]="Saida", RANDBETWEEN(1, _xlpm.saldo_atual), RANDBETWEEN(1, 100) ), IF( Tabela_Movimentacao_Geral[[#This Row],[Tipo Fluxo]]="Saida", RANDBETWEEN(1, _xlpm.saldo_atual), IF( _xlpm.saldo_atual < 0, ABS(_xlpm.saldo_atual) + _xlpm.estoque_minimo + RANDBETWEEN(1, 100), _xlpm.estoque_minimo - _xlpm.saldo_atual + RANDBETWEEN(1, 100) ) ) ) ), Tabela_Movimentacao_Geral[[#This Row],[Quantidade]] )} -> 29 | I22: =_xlfn.XLOOKUP(Tabela_Movimentacao_Geral[[#This Row],[ID Produto]], Tabela_Produtos[ID_Produto],Tabela_Produtos[Preco_Unitario_Venda]) -> 120 | J22: =Tabela_Movimentacao_Geral[[#This Row],[Quantidade]] * Tabela_Movimentacao_Geral[[#This Row],[Valor Unitário]] -> 3480 | K22: =IF( $O$7="Desbloqueado", CHOOSE(RANDBETWEEN(1,3),"Pago","Pendente","Atrasado"), Tabela_Movimentacao_Geral[[#This Row],[Status Financeiro]] ) -> Atrasado | L22: =IF( $O$7="Desbloqueado", CHOOSE(RANDBETWEEN(1,3),"Entregue","Em Rota","Aguardando"), Tabela_Movimentacao_Geral[[#This Row],[Status Logistico]] ) -> Em Rota | M22: =IF( $O$7="Desbloqueado", IF( Tabela_Movimentacao_Geral[[#This Row],[Tipo Fluxo]]="Entrada", Tabela_Movimentacao_Geral[[#This Row],[Data]] + _xlfn.XLOOKUP(Tabela_Movimentacao_Geral[[#This Row],[ID Entidade]],Tabela_Fornecedores[ID_Fornecedor],Tabela_Fornecedores[Lead_Time]), "N/A" ), Tabela_Movimentacao_Geral[[#This Row],[Previsão de Entrega]] ) -> 0
A23: ="T"&TEXT(ROW(A23)-1,"0000") -> T0022 | B23: 45677 | C23: {=IF($O$7="Desbloqueado", _xlfn.LET( _xlpm.saldo_atual, SUM(($C$2:$C22="Entrada")*($F$2:$F22=Tabela_Movimentacao_Geral[[#This Row],[ID Produto]])*($H$2:$H22) - ($C$2:$C22="Saida")*($F$2:$F22=Tabela_Movimentacao_Geral[[#This Row],[ID Produto]])*($H$2:$H22)), IF(_xlpm.saldo_atual > 0, IF(RANDBETWEEN(0,10)>3,"Saida","Entrada"), "Entrada") ), Tabela_Movimentacao_Geral[[#This Row],[Tipo Fluxo]] )} -> Entrada | D23: =IF( $O$7="Desbloqueado", IF( Tabela_Movimentacao_Geral[[#This Row],[Tipo Fluxo]]="Saida", "CLI"&TEXT(RANDBETWEEN(1,20),"000"), "FORN"&TEXT(RANDBETWEEN(1,20),"000") ), Tabela_Movimentacao_Geral[[#This Row],[ID Entidade]] ) -> FORN007 | E23: =IF(Tabela_Movimentacao_Geral[[#This Row],[Tipo Fluxo]]="Saida",_xlfn.XLOOKUP(Tabela_Movimentacao_Geral[[#This Row],[ID Entidade]], Tabela_Clientes[ID_Cliente],Tabela_Clientes[Nome_Cliente],"Cliente não encontrado"),_xlfn.XLOOKUP(Tabela_Movimentacao_Geral[[#This Row],[ID Entidade]], Tabela_Fornecedores[ID_Fornecedor], Tabela_Fornecedores[Nome_Fantasia], "Fornecedor não encontrado")) -> CyberSecurity SA | F23: =IF( $O$7="Desbloqueado", "PROD"&TEXT(RANDBETWEEN(1,200),"000"), Tabela_Movimentacao_Geral[[#This Row],[ID Produto]] ) -> PROD157 | G23: =_xlfn.XLOOKUP(Tabela_Movimentacao_Geral[[#This Row],[ID Produto]], Tabela_Produtos[ID_Produto],Tabela_Produtos[Descricao_Produto],"Produto não encontrado") -> Fita Dupla Face 3M | H23: {=IF( $O$7="Desbloqueado", _xlfn.LET( _xlpm.saldo_atual, SUM(($C$2:$C22="Entrada")*($F$2:$F22=Tabela_Movimentacao_Geral[[#This Row],[ID Produto]])*($H$2:$H22) - ($C$2:$C22="Saida")*($F$2:$F22=Tabela_Movimentacao_Geral[[#This Row],[ID Produto]])*($H$2:$H22)), _xlpm.estoque_minimo, _xlfn.XLOOKUP(Tabela_Movimentacao_Geral[[#This Row],[ID Produto]], Tabela_Produtos[ID_Produto], Tabela_Produtos[Estoque_Minimo], 0), IF( _xlpm.saldo_atual > _xlpm.estoque_minimo, IF( Tabela_Movimentacao_Geral[[#This Row],[Tipo Fluxo]]="Saida", RANDBETWEEN(1, _xlpm.saldo_atual), RANDBETWEEN(1, 100) ), IF( Tabela_Movimentacao_Geral[[#This Row],[Tipo Fluxo]]="Saida", RANDBETWEEN(1, _xlpm.saldo_atual), IF( _xlpm.saldo_atual < 0, ABS(_xlpm.saldo_atual) + _xlpm.estoque_minimo + RANDBETWEEN(1, 100), _xlpm.estoque_minimo - _xlpm.saldo_atual + RANDBETWEEN(1, 100) ) ) ) ), Tabela_Movimentacao_Geral[[#This Row],[Quantidade]] )} -> 95 | I23: =_xlfn.XLOOKUP(Tabela_Movimentacao_Geral[[#This Row],[ID Produto]], Tabela_Produtos[ID_Produto],Tabela_Produtos[Preco_Unitario_Venda]) -> 28 | J23: =Tabela_Movimentacao_Geral[[#This Row],[Quantidade]] * Tabela_Movimentacao_Geral[[#This Row],[Valor Unitário]] -> 2660 | K23: =IF( $O$7="Desbloqueado", CHOOSE(RANDBETWEEN(1,3),"Pago","Pendente","Atrasado"), Tabela_Movimentacao_Geral[[#This Row],[Status Financeiro]] ) -> Pendente | L23: =IF( $O$7="Desbloqueado", CHOOSE(RANDBETWEEN(1,3),"Entregue","Em Rota","Aguardando"), Tabela_Movimentacao_Geral[[#This Row],[Status Logistico]] ) -> Entregue | M23: =IF( $O$7="Desbloqueado", IF( Tabela_Movimentacao_Geral[[#This Row],[Tipo Fluxo]]="Entrada", Tabela_Movimentacao_Geral[[#This Row],[Data]] + _xlfn.XLOOKUP(Tabela_Movimentacao_Geral[[#This Row],[ID Entidade]],Tabela_Fornecedores[ID_Fornecedor],Tabela_Fornecedores[Lead_Time]), "N/A" ), Tabela_Movimentacao_Geral[[#This Row],[Previsão de Entrega]] ) -> 45684
A24: ="T"&TEXT(ROW(A24)-1,"0000") -> T0023 | B24: 45677 | C24: {=IF($O$7="Desbloqueado", _xlfn.LET( _xlpm.saldo_atual, SUM(($C$2:$C23="Entrada")*($F$2:$F23=Tabela_Movimentacao_Geral[[#This Row],[ID Produto]])*($H$2:$H23) - ($C$2:$C23="Saida")*($F$2:$F23=Tabela_Movimentacao_Geral[[#This Row],[ID Produto]])*($H$2:$H23)), IF(_xlpm.saldo_atual > 0, IF(RANDBETWEEN(0,10)>3,"Saida","Entrada"), "Entrada") ), Tabela_Movimentacao_Geral[[#This Row],[Tipo Fluxo]] )} -> Entrada | D24: =IF( $O$7="Desbloqueado", IF( Tabela_Movimentacao_Geral[[#This Row],[Tipo Fluxo]]="Saida", "CLI"&TEXT(RANDBETWEEN(1,20),"000"), "FORN"&TEXT(RANDBETWEEN(1,20),"000") ), Tabela_Movimentacao_Geral[[#This Row],[ID Entidade]] ) -> FORN001 | E24: =IF(Tabela_Movimentacao_Geral[[#This Row],[Tipo Fluxo]]="Saida",_xlfn.XLOOKUP(Tabela_Movimentacao_Geral[[#This Row],[ID Entidade]], Tabela_Clientes[ID_Cliente],Tabela_Clientes[Nome_Cliente],"Cliente não encontrado"),_xlfn.XLOOKUP(Tabela_Movimentacao_Geral[[#This Row],[ID Entidade]], Tabela_Fornecedores[ID_Fornecedor], Tabela_Fornecedores[Nome_Fantasia], "Fornecedor não encontrado")) -> TechFlow Solucoes | F24: =IF( $O$7="Desbloqueado", "PROD"&TEXT(RANDBETWEEN(1,200),"000"), Tabela_Movimentacao_Geral[[#This Row],[ID Produto]] ) -> PROD074 | G24: =_xlfn.XLOOKUP(Tabela_Movimentacao_Geral[[#This Row],[ID Produto]], Tabela_Produtos[ID_Produto],Tabela_Produtos[Descricao_Produto],"Produto não encontrado") -> Cordao para Cracha | H24: {=IF( $O$7="Desbloqueado", _xlfn.LET( _xlpm.saldo_atual, SUM(($C$2:$C23="Entrada")*($F$2:$F23=Tabela_Movimentacao_Geral[[#This Row],[ID Produto]])*($H$2:$H23) - ($C$2:$C23="Saida")*($F$2:$F23=Tabela_Movimentacao_Geral[[#This Row],[ID Produto]])*($H$2:$H23)), _xlpm.estoque_minimo, _xlfn.XLOOKUP(Tabela_Movimentacao_Geral[[#This Row],[ID Produto]], Tabela_Produtos[ID_Produto], Tabela_Produtos[Estoque_Minimo], 0), IF( _xlpm.saldo_atual > _xlpm.estoque_minimo, IF( Tabela_Movimentacao_Geral[[#This Row],[Tipo Fluxo]]="Saida", RANDBETWEEN(1, _xlpm.saldo_atual), RANDBETWEEN(1, 100) ), IF( Tabela_Movimentacao_Geral[[#This Row],[Tipo Fluxo]]="Saida", RANDBETWEEN(1, _xlpm.saldo_atual), IF( _xlpm.saldo_atual < 0, ABS(_xlpm.saldo_atual) + _xlpm.estoque_minimo + RANDBETWEEN(1, 100), _xlpm.estoque_minimo - _xlpm.saldo_atual + RANDBETWEEN(1, 100) ) ) ) ), Tabela_Movimentacao_Geral[[#This Row],[Quantidade]] )} -> 372 | I24: =_xlfn.XLOOKUP(Tabela_Movimentacao_Geral[[#This Row],[ID Produto]], Tabela_Produtos[ID_Produto],Tabela_Produtos[Preco_Unitario_Venda]) -> 3.5 | J24: =Tabela_Movimentacao_Geral[[#This Row],[Quantidade]] * Tabela_Movimentacao_Geral[[#This Row],[Valor Unitário]] -> 1302 | K24: =IF( $O$7="Desbloqueado", CHOOSE(RANDBETWEEN(1,3),"Pago","Pendente","Atrasado"), Tabela_Movimentacao_Geral[[#This Row],[Status Financeiro]] ) -> Pago | L24: =IF( $O$7="Desbloqueado", CHOOSE(RANDBETWEEN(1,3),"Entregue","Em Rota","Aguardando"), Tabela_Movimentacao_Geral[[#This Row],[Status Logistico]] ) -> Em Rota | M24: =IF( $O$7="Desbloqueado", IF( Tabela_Movimentacao_Geral[[#This Row],[Tipo Fluxo]]="Entrada", Tabela_Movimentacao_Geral[[#This Row],[Data]] + _xlfn.XLOOKUP(Tabela_Movimentacao_Geral[[#This Row],[ID Entidade]],Tabela_Fornecedores[ID_Fornecedor],Tabela_Fornecedores[Lead_Time]), "N/A" ), Tabela_Movimentacao_Geral[[#This Row],[Previsão de Entrega]] ) -> 45682
A25: ="T"&TEXT(ROW(A25)-1,"0000") -> T0024 | B25: 45678 | C25: {=IF($O$7="Desbloqueado", _xlfn.LET( _xlpm.saldo_atual, SUM(($C$2:$C24="Entrada")*($F$2:$F24=Tabela_Movimentacao_Geral[[#This Row],[ID Produto]])*($H$2:$H24) - ($C$2:$C24="Saida")*($F$2:$F24=Tabela_Movimentacao_Geral[[#This Row],[ID Produto]])*($H$2:$H24)), IF(_xlpm.saldo_atual > 0, IF(RANDBETWEEN(0,10)>3,"Saida","Entrada"), "Entrada") ), Tabela_Movimentacao_Geral[[#This Row],[Tipo Fluxo]] )} -> Entrada | D25: =IF( $O$7="Desbloqueado", IF( Tabela_Movimentacao_Geral[[#This Row],[Tipo Fluxo]]="Saida", "CLI"&TEXT(RANDBETWEEN(1,20),"000"), "FORN"&TEXT(RANDBETWEEN(1,20),"000") ), Tabela_Movimentacao_Geral[[#This Row],[ID Entidade]] ) -> FORN009 | E25: =IF(Tabela_Movimentacao_Geral[[#This Row],[Tipo Fluxo]]="Saida",_xlfn.XLOOKUP(Tabela_Movimentacao_Geral[[#This Row],[ID Entidade]], Tabela_Clientes[ID_Cliente],Tabela_Clientes[Nome_Cliente],"Cliente não encontrado"),_xlfn.XLOOKUP(Tabela_Movimentacao_Geral[[#This Row],[ID Entidade]], Tabela_Fornecedores[ID_Fornecedor], Tabela_Fornecedores[Nome_Fantasia], "Fornecedor não encontrado")) -> Movel Tech | F25: =IF( $O$7="Desbloqueado", "PROD"&TEXT(RANDBETWEEN(1,200),"000"), Tabela_Movimentacao_Geral[[#This Row],[ID Produto]] ) -> PROD175 | G25: =_xlfn.XLOOKUP(Tabela_Movimentacao_Geral[[#This Row],[ID Produto]], Tabela_Produtos[ID_Produto],Tabela_Produtos[Descricao_Produto],"Produto não encontrado") -> Plastico Bolha 1.2x50m | H25: {=IF( $O$7="Desbloqueado", _xlfn.LET( _xlpm.saldo_atual, SUM(($C$2:$C24="Entrada")*($F$2:$F24=Tabela_Movimentacao_Geral[[#This Row],[ID Produto]])*($H$2:$H24) - ($C$2:$C24="Saida")*($F$2:$F24=Tabela_Movimentacao_Geral[[#This Row],[ID Produto]])*($H$2:$H24)), _xlpm.estoque_minimo, _xlfn.XLOOKUP(Tabela_Movimentacao_Geral[[#This Row],[ID Produto]], Tabela_Produtos[ID_Produto], Tabela_Produtos[Estoque_Minimo], 0), IF( _xlpm.saldo_atual > _xlpm.estoque_minimo, IF( Tabela_Movimentacao_Geral[[#This Row],[Tipo Fluxo]]="Saida", RANDBETWEEN(1, _xlpm.saldo_atual), RANDBETWEEN(1, 100) ), IF( Tabela_Movimentacao_Geral[[#This Row],[Tipo Fluxo]]="Saida", RANDBETWEEN(1, _xlpm.saldo_atual), IF( _xlpm.saldo_atual < 0, ABS(_xlpm.saldo_atual) + _xlpm.estoque_minimo + RANDBETWEEN(1, 100), _xlpm.estoque_minimo - _xlpm.saldo_atual + RANDBETWEEN(1, 100) ) ) ) ), Tabela_Movimentacao_Geral[[#This Row],[Quantidade]] )} -> 99 | I25: =_xlfn.XLOOKUP(Tabela_Movimentacao_Geral[[#This Row],[ID Produto]], Tabela_Produtos[ID_Produto],Tabela_Produtos[Preco_Unitario_Venda]) -> 110 | J25: =Tabela_Movimentacao_Geral[[#This Row],[Quantidade]] * Tabela_Movimentacao_Geral[[#This Row],[Valor Unitário]] -> 10890 | K25: =IF( $O$7="Desbloqueado", CHOOSE(RANDBETWEEN(1,3),"Pago","Pendente","Atrasado"), Tabela_Movimentacao_Geral[[#This Row],[Status Financeiro]] ) -> Pago | L25: =IF( $O$7="Desbloqueado", CHOOSE(RANDBETWEEN(1,3),"Entregue","Em Rota","Aguardando"), Tabela_Movimentacao_Geral[[#This Row],[Status Logistico]] ) -> Em Rota | M25: =IF( $O$7="Desbloqueado", IF( Tabela_Movimentacao_Geral[[#This Row],[Tipo Fluxo]]="Entrada", Tabela_Movimentacao_Geral[[#This Row],[Data]] + _xlfn.XLOOKUP(Tabela_Movimentacao_Geral[[#This Row],[ID Entidade]],Tabela_Fornecedores[ID_Fornecedor],Tabela_Fornecedores[Lead_Time]), "N/A" ), Tabela_Movimentacao_Geral[[#This Row],[Previsão de Entrega]] ) -> 45688
A26: ="T"&TEXT(ROW(A26)-1,"0000") -> T0025 | B26: 45679 | C26: {=IF($O$7="Desbloqueado", _xlfn.LET( _xlpm.saldo_atual, SUM(($C$2:$C25="Entrada")*($F$2:$F25=Tabela_Movimentacao_Geral[[#This Row],[ID Produto]])*($H$2:$H25) - ($C$2:$C25="Saida")*($F$2:$F25=Tabela_Movimentacao_Geral[[#This Row],[ID Produto]])*($H$2:$H25)), IF(_xlpm.saldo_atual > 0, IF(RANDBETWEEN(0,10)>3,"Saida","Entrada"), "Entrada") ), Tabela_Movimentacao_Geral[[#This Row],[Tipo Fluxo]] )} -> Entrada | D26: =IF( $O$7="Desbloqueado", IF( Tabela_Movimentacao_Geral[[#This Row],[Tipo Fluxo]]="Saida", "CLI"&TEXT(RANDBETWEEN(1,20),"000"), "FORN"&TEXT(RANDBETWEEN(1,20),"000") ), Tabela_Movimentacao_Geral[[#This Row],[ID Entidade]] ) -> FORN001 | E26: =IF(Tabela_Movimentacao_Geral[[#This Row],[Tipo Fluxo]]="Saida",_xlfn.XLOOKUP(Tabela_Movimentacao_Geral[[#This Row],[ID Entidade]], Tabela_Clientes[ID_Cliente],Tabela_Clientes[Nome_Cliente],"Cliente não encontrado"),_xlfn.XLOOKUP(Tabela_Movimentacao_Geral[[#This Row],[ID Entidade]], Tabela_Fornecedores[ID_Fornecedor], Tabela_Fornecedores[Nome_Fantasia], "Fornecedor não encontrado")) -> TechFlow Solucoes | F26: =IF( $O$7="Desbloqueado", "PROD"&TEXT(RANDBETWEEN(1,200),"000"), Tabela_Movimentacao_Geral[[#This Row],[ID Produto]] ) -> PROD128 | G26: =_xlfn.XLOOKUP(Tabela_Movimentacao_Geral[[#This Row],[ID Produto]], Tabela_Produtos[ID_Produto],Tabela_Produtos[Descricao_Produto],"Produto não encontrado") -> Cabo de Rede Cat5e 5m | H26: {=IF( $O$7="Desbloqueado", _xlfn.LET( _xlpm.saldo_atual, SUM(($C$2:$C25="Entrada")*($F$2:$F25=Tabela_Movimentacao_Geral[[#This Row],[ID Produto]])*($H$2:$H25) - ($C$2:$C25="Saida")*($F$2:$F25=Tabela_Movimentacao_Geral[[#This Row],[ID Produto]])*($H$2:$H25)), _xlpm.estoque_minimo, _xlfn.XLOOKUP(Tabela_Movimentacao_Geral[[#This Row],[ID Produto]], Tabela_Produtos[ID_Produto], Tabela_Produtos[Estoque_Minimo], 0), IF( _xlpm.saldo_atual > _xlpm.estoque_minimo, IF( Tabela_Movimentacao_Geral[[#This Row],[Tipo Fluxo]]="Saida", RANDBETWEEN(1, _xlpm.saldo_atual), RANDBETWEEN(1, 100) ), IF( Tabela_Movimentacao_Geral[[#This Row],[Tipo Fluxo]]="Saida", RANDBETWEEN(1, _xlpm.saldo_atual), IF( _xlpm.saldo_atual < 0, ABS(_xlpm.saldo_atual) + _xlpm.estoque_minimo + RANDBETWEEN(1, 100), _xlpm.estoque_minimo - _xlpm.saldo_atual + RANDBETWEEN(1, 100) ) ) ) ), Tabela_Movimentacao_Geral[[#This Row],[Quantidade]] )} -> 179 | I26: =_xlfn.XLOOKUP(Tabela_Movimentacao_Geral[[#This Row],[ID Produto]], Tabela_Produtos[ID_Produto],Tabela_Produtos[Preco_Unitario_Venda]) -> 18 | J26: =Tabela_Movimentacao_Geral[[#This Row],[Quantidade]] * Tabela_Movimentacao_Geral[[#This Row],[Valor Unitário]] -> 3222 | K26: =IF( $O$7="Desbloqueado", CHOOSE(RANDBETWEEN(1,3),"Pago","Pendente","Atrasado"), Tabela_Movimentacao_Geral[[#This Row],[Status Financeiro]] ) -> Pendente | L26: =IF( $O$7="Desbloqueado", CHOOSE(RANDBETWEEN(1,3),"Entregue","Em Rota","Aguardando"), Tabela_Movimentacao_Geral[[#This Row],[Status Logistico]] ) -> Aguardando | M26: =IF( $O$7="Desbloqueado", IF( Tabela_Movimentacao_Geral[[#This Row],[Tipo Fluxo]]="Entrada", Tabela_Movimentacao_Geral[[#This Row],[Data]] + _xlfn.XLOOKUP(Tabela_Movimentacao_Geral[[#This Row],[ID Entidade]],Tabela_Fornecedores[ID_Fornecedor],Tabela_Fornecedores[Lead_Time]), "N/A" ), Tabela_Movimentacao_Geral[[#This Row],[Previsão de Entrega]] ) -> 45684
A27: ="T"&TEXT(ROW(A27)-1,"0000") -> T0026 | B27: 45679 | C27: {=IF($O$7="Desbloqueado", _xlfn.LET( _xlpm.saldo_atual, SUM(($C$2:$C26="Entrada")*($F$2:$F26=Tabela_Movimentacao_Geral[[#This Row],[ID Produto]])*($H$2:$H26) - ($C$2:$C26="Saida")*($F$2:$F26=Tabela_Movimentacao_Geral[[#This Row],[ID Produto]])*($H$2:$H26)), IF(_xlpm.saldo_atual > 0, IF(RANDBETWEEN(0,10)>3,"Saida","Entrada"), "Entrada") ), Tabela_Movimentacao_Geral[[#This Row],[Tipo Fluxo]] )} -> Entrada | D27: =IF( $O$7="Desbloqueado", IF( Tabela_Movimentacao_Geral[[#This Row],[Tipo Fluxo]]="Saida", "CLI"&TEXT(RANDBETWEEN(1,20),"000"), "FORN"&TEXT(RANDBETWEEN(1,20),"000") ), Tabela_Movimentacao_Geral[[#This Row],[ID Entidade]] ) -> FORN010 | E27: =IF(Tabela_Movimentacao_Geral[[#This Row],[Tipo Fluxo]]="Saida",_xlfn.XLOOKUP(Tabela_Movimentacao_Geral[[#This Row],[ID Entidade]], Tabela_Clientes[ID_Cliente],Tabela_Clientes[Nome_Cliente],"Cliente não encontrado"),_xlfn.XLOOKUP(Tabela_Movimentacao_Geral[[#This Row],[ID Entidade]], Tabela_Fornecedores[ID_Fornecedor], Tabela_Fornecedores[Nome_Fantasia], "Fornecedor não encontrado")) -> DataCenter Pro | F27: =IF( $O$7="Desbloqueado", "PROD"&TEXT(RANDBETWEEN(1,200),"000"), Tabela_Movimentacao_Geral[[#This Row],[ID Produto]] ) -> PROD135 | G27: =_xlfn.XLOOKUP(Tabela_Movimentacao_Geral[[#This Row],[ID Produto]], Tabela_Produtos[ID_Produto],Tabela_Produtos[Descricao_Produto],"Produto não encontrado") -> Ponteira Laser Apresentador | H27: {=IF( $O$7="Desbloqueado", _xlfn.LET( _xlpm.saldo_atual, SUM(($C$2:$C26="Entrada")*($F$2:$F26=Tabela_Movimentacao_Geral[[#This Row],[ID Produto]])*($H$2:$H26) - ($C$2:$C26="Saida")*($F$2:$F26=Tabela_Movimentacao_Geral[[#This Row],[ID Produto]])*($H$2:$H26)), _xlpm.estoque_minimo, _xlfn.XLOOKUP(Tabela_Movimentacao_Geral[[#This Row],[ID Produto]], Tabela_Produtos[ID_Produto], Tabela_Produtos[Estoque_Minimo], 0), IF( _xlpm.saldo_atual > _xlpm.estoque_minimo, IF( Tabela_Movimentacao_Geral[[#This Row],[Tipo Fluxo]]="Saida", RANDBETWEEN(1, _xlpm.saldo_atual), RANDBETWEEN(1, 100) ), IF( Tabela_Movimentacao_Geral[[#This Row],[Tipo Fluxo]]="Saida", RANDBETWEEN(1, _xlpm.saldo_atual), IF( _xlpm.saldo_atual < 0, ABS(_xlpm.saldo_atual) + _xlpm.estoque_minimo + RANDBETWEEN(1, 100), _xlpm.estoque_minimo - _xlpm.saldo_atual + RANDBETWEEN(1, 100) ) ) ) ), Tabela_Movimentacao_Geral[[#This Row],[Quantidade]] )} -> 42 | I27: =_xlfn.XLOOKUP(Tabela_Movimentacao_Geral[[#This Row],[ID Produto]], Tabela_Produtos[ID_Produto],Tabela_Produtos[Preco_Unitario_Venda]) -> 120 | J27: =Tabela_Movimentacao_Geral[[#This Row],[Quantidade]] * Tabela_Movimentacao_Geral[[#This Row],[Valor Unitário]] -> 5040 | K27: =IF( $O$7="Desbloqueado", CHOOSE(RANDBETWEEN(1,3),"Pago","Pendente","Atrasado"), Tabela_Movimentacao_Geral[[#This Row],[Status Financeiro]] ) -> Pago | L27: =IF( $O$7="Desbloqueado", CHOOSE(RANDBETWEEN(1,3),"Entregue","Em Rota","Aguardando"), Tabela_Movimentacao_Geral[[#This Row],[Status Logistico]] ) -> Em Rota | M27: =IF( $O$7="Desbloqueado", IF( Tabela_Movimentacao_Geral[[#This Row],[Tipo Fluxo]]="Entrada", Tabela_Movimentacao_Geral[[#This Row],[Data]] + _xlfn.XLOOKUP(Tabela_Movimentacao_Geral[[#This Row],[ID Entidade]],Tabela_Fornecedores[ID_Fornecedor],Tabela_Fornecedores[Lead_Time]), "N/A" ), Tabela_Movimentacao_Geral[[#This Row],[Previsão de Entrega]] ) -> 45681
A28: ="T"&TEXT(ROW(A28)-1,"0000") -> T0027 | B28: 45679 | C28: {=IF($O$7="Desbloqueado", _xlfn.LET( _xlpm.saldo_atual, SUM(($C$2:$C27="Entrada")*($F$2:$F27=Tabela_Movimentacao_Geral[[#This Row],[ID Produto]])*($H$2:$H27) - ($C$2:$C27="Saida")*($F$2:$F27=Tabela_Movimentacao_Geral[[#This Row],[ID Produto]])*($H$2:$H27)), IF(_xlpm.saldo_atual > 0, IF(RANDBETWEEN(0,10)>3,"Saida","Entrada"), "Entrada") ), Tabela_Movimentacao_Geral[[#This Row],[Tipo Fluxo]] )} -> Entrada | D28: =IF( $O$7="Desbloqueado", IF( Tabela_Movimentacao_Geral[[#This Row],[Tipo Fluxo]]="Saida", "CLI"&TEXT(RANDBETWEEN(1,20),"000"), "FORN"&TEXT(RANDBETWEEN(1,20),"000") ), Tabela_Movimentacao_Geral[[#This Row],[ID Entidade]] ) -> FORN008 | E28: =IF(Tabela_Movimentacao_Geral[[#This Row],[Tipo Fluxo]]="Saida",_xlfn.XLOOKUP(Tabela_Movimentacao_Geral[[#This Row],[ID Entidade]], Tabela_Clientes[ID_Cliente],Tabela_Clientes[Nome_Cliente],"Cliente não encontrado"),_xlfn.XLOOKUP(Tabela_Movimentacao_Geral[[#This Row],[ID Entidade]], Tabela_Fornecedores[ID_Fornecedor], Tabela_Fornecedores[Nome_Fantasia], "Fornecedor não encontrado")) -> Global Chips | F28: =IF( $O$7="Desbloqueado", "PROD"&TEXT(RANDBETWEEN(1,200),"000"), Tabela_Movimentacao_Geral[[#This Row],[ID Produto]] ) -> PROD150 | G28: =_xlfn.XLOOKUP(Tabela_Movimentacao_Geral[[#This Row],[ID Produto]], Tabela_Produtos[ID_Produto],Tabela_Produtos[Descricao_Produto],"Produto não encontrado") -> Lanterna de Led Inspeção | H28: {=IF( $O$7="Desbloqueado", _xlfn.LET( _xlpm.saldo_atual, SUM(($C$2:$C27="Entrada")*($F$2:$F27=Tabela_Movimentacao_Geral[[#This Row],[ID Produto]])*($H$2:$H27) - ($C$2:$C27="Saida")*($F$2:$F27=Tabela_Movimentacao_Geral[[#This Row],[ID Produto]])*($H$2:$H27)), _xlpm.estoque_minimo, _xlfn.XLOOKUP(Tabela_Movimentacao_Geral[[#This Row],[ID Produto]], Tabela_Produtos[ID_Produto], Tabela_Produtos[Estoque_Minimo], 0), IF( _xlpm.saldo_atual > _xlpm.estoque_minimo, IF( Tabela_Movimentacao_Geral[[#This Row],[Tipo Fluxo]]="Saida", RANDBETWEEN(1, _xlpm.saldo_atual), RANDBETWEEN(1, 100) ), IF( Tabela_Movimentacao_Geral[[#This Row],[Tipo Fluxo]]="Saida", RANDBETWEEN(1, _xlpm.saldo_atual), IF( _xlpm.saldo_atual < 0, ABS(_xlpm.saldo_atual) + _xlpm.estoque_minimo + RANDBETWEEN(1, 100), _xlpm.estoque_minimo - _xlpm.saldo_atual + RANDBETWEEN(1, 100) ) ) ) ), Tabela_Movimentacao_Geral[[#This Row],[Quantidade]] )} -> 73 | I28: =_xlfn.XLOOKUP(Tabela_Movimentacao_Geral[[#This Row],[ID Produto]], Tabela_Produtos[ID_Produto],Tabela_Produtos[Preco_Unitario_Venda]) -> 55 | J28: =Tabela_Movimentacao_Geral[[#This Row],[Quantidade]] * Tabela_Movimentacao_Geral[[#This Row],[Valor Unitário]] -> 4015 | K28: =IF( $O$7="Desbloqueado", CHOOSE(RANDBETWEEN(1,3),"Pago","Pendente","Atrasado"), Tabela_Movimentacao_Geral[[#This Row],[Status Financeiro]] ) -> Pendente | L28: =IF( $O$7="Desbloqueado", CHOOSE(RANDBETWEEN(1,3),"Entregue","Em Rota","Aguardando"), Tabela_Movimentacao_Geral[[#This Row],[Status Logistico]] ) -> Em Rota | M28: =IF( $O$7="Desbloqueado", IF( Tabela_Movimentacao_Geral[[#This Row],[Tipo Fluxo]]="Entrada", Tabela_Movimentacao_Geral[[#This Row],[Data]] + _xlfn.XLOOKUP(Tabela_Movimentacao_Geral[[#This Row],[ID Entidade]],Tabela_Fornecedores[ID_Fornecedor],Tabela_Fornecedores[Lead_Time]), "N/A" ), Tabela_Movimentacao_Geral[[#This Row],[Previsão de Entrega]] ) -> 45694
A29: ="T"&TEXT(ROW(A29)-1,"0000") -> T0028 | B29: 45679 | C29: {=IF($O$7="Desbloqueado", _xlfn.LET( _xlpm.saldo_atual, SUM(($C$2:$C28="Entrada")*($F$2:$F28=Tabela_Movimentacao_Geral[[#This Row],[ID Produto]])*($H$2:$H28) - ($C$2:$C28="Saida")*($F$2:$F28=Tabela_Movimentacao_Geral[[#This Row],[ID Produto]])*($H$2:$H28)), IF(_xlpm.saldo_atual > 0, IF(RANDBETWEEN(0,10)>3,"Saida","Entrada"), "Entrada") ), Tabela_Movimentacao_Geral[[#This Row],[Tipo Fluxo]] )} -> Entrada | D29: =IF( $O$7="Desbloqueado", IF( Tabela_Movimentacao_Geral[[#This Row],[Tipo Fluxo]]="Saida", "CLI"&TEXT(RANDBETWEEN(1,20),"000"), "FORN"&TEXT(RANDBETWEEN(1,20),"000") ), Tabela_Movimentacao_Geral[[#This Row],[ID Entidade]] ) -> FORN015 | E29: =IF(Tabela_Movimentacao_Geral[[#This Row],[Tipo Fluxo]]="Saida",_xlfn.XLOOKUP(Tabela_Movimentacao_Geral[[#This Row],[ID Entidade]], Tabela_Clientes[ID_Cliente],Tabela_Clientes[Nome_Cliente],"Cliente não encontrado"),_xlfn.XLOOKUP(Tabela_Movimentacao_Geral[[#This Row],[ID Entidade]], Tabela_Fornecedores[ID_Fornecedor], Tabela_Fornecedores[Nome_Fantasia], "Fornecedor não encontrado")) -> Print Smart | F29: =IF( $O$7="Desbloqueado", "PROD"&TEXT(RANDBETWEEN(1,200),"000"), Tabela_Movimentacao_Geral[[#This Row],[ID Produto]] ) -> PROD195 | G29: =_xlfn.XLOOKUP(Tabela_Movimentacao_Geral[[#This Row],[ID Produto]], Tabela_Produtos[ID_Produto],Tabela_Produtos[Descricao_Produto],"Produto não encontrado") -> Terminador Optico | H29: {=IF( $O$7="Desbloqueado", _xlfn.LET( _xlpm.saldo_atual, SUM(($C$2:$C28="Entrada")*($F$2:$F28=Tabela_Movimentacao_Geral[[#This Row],[ID Produto]])*($H$2:$H28) - ($C$2:$C28="Saida")*($F$2:$F28=Tabela_Movimentacao_Geral[[#This Row],[ID Produto]])*($H$2:$H28)), _xlpm.estoque_minimo, _xlfn.XLOOKUP(Tabela_Movimentacao_Geral[[#This Row],[ID Produto]], Tabela_Produtos[ID_Produto], Tabela_Produtos[Estoque_Minimo], 0), IF( _xlpm.saldo_atual > _xlpm.estoque_minimo, IF( Tabela_Movimentacao_Geral[[#This Row],[Tipo Fluxo]]="Saida", RANDBETWEEN(1, _xlpm.saldo_atual), RANDBETWEEN(1, 100) ), IF( Tabela_Movimentacao_Geral[[#This Row],[Tipo Fluxo]]="Saida", RANDBETWEEN(1, _xlpm.saldo_atual), IF( _xlpm.saldo_atual < 0, ABS(_xlpm.saldo_atual) + _xlpm.estoque_minimo + RANDBETWEEN(1, 100), _xlpm.estoque_minimo - _xlpm.saldo_atual + RANDBETWEEN(1, 100) ) ) ) ), Tabela_Movimentacao_Geral[[#This Row],[Quantidade]] )} -> 83 | I29: =_xlfn.XLOOKUP(Tabela_Movimentacao_Geral[[#This Row],[ID Produto]], Tabela_Produtos[ID_Produto],Tabela_Produtos[Preco_Unitario_Venda]) -> 120 | J29: =Tabela_Movimentacao_Geral[[#This Row],[Quantidade]] * Tabela_Movimentacao_Geral[[#This Row],[Valor Unitário]] -> 9960 | K29: =IF( $O$7="Desbloqueado", CHOOSE(RANDBETWEEN(1,3),"Pago","Pendente","Atrasado"), Tabela_Movimentacao_Geral[[#This Row],[Status Financeiro]] ) -> Pendente | L29: =IF( $O$7="Desbloqueado", CHOOSE(RANDBETWEEN(1,3),"Entregue","Em Rota","Aguardando"), Tabela_Movimentacao_Geral[[#This Row],[Status Logistico]] ) -> Aguardando | M29: =IF( $O$7="Desbloqueado", IF( Tabela_Movimentacao_Geral[[#This Row],[Tipo Fluxo]]="Entrada", Tabela_Movimentacao_Geral[[#This Row],[Data]] + _xlfn.XLOOKUP(Tabela_Movimentacao_Geral[[#This Row],[ID Entidade]],Tabela_Fornecedores[ID_Fornecedor],Tabela_Fornecedores[Lead_Time]), "N/A" ), Tabela_Movimentacao_Geral[[#This Row],[Previsão de Entrega]] ) -> 45682
A30: ="T"&TEXT(ROW(A30)-1,"0000") -> T0029 | B30: 45679 | C30: {=IF($O$7="Desbloqueado", _xlfn.LET( _xlpm.saldo_atual, SUM(($C$2:$C29="Entrada")*($F$2:$F29=Tabela_Movimentacao_Geral[[#This Row],[ID Produto]])*($H$2:$H29) - ($C$2:$C29="Saida")*($F$2:$F29=Tabela_Movimentacao_Geral[[#This Row],[ID Produto]])*($H$2:$H29)), IF(_xlpm.saldo_atual > 0, IF(RANDBETWEEN(0,10)>3,"Saida","Entrada"), "Entrada") ), Tabela_Movimentacao_Geral[[#This Row],[Tipo Fluxo]] )} -> Entrada | D30: =IF( $O$7="Desbloqueado", IF( Tabela_Movimentacao_Geral[[#This Row],[Tipo Fluxo]]="Saida", "CLI"&TEXT(RANDBETWEEN(1,20),"000"), "FORN"&TEXT(RANDBETWEEN(1,20),"000") ), Tabela_Movimentacao_Geral[[#This Row],[ID Entidade]] ) -> FORN001 | E30: =IF(Tabela_Movimentacao_Geral[[#This Row],[Tipo Fluxo]]="Saida",_xlfn.XLOOKUP(Tabela_Movimentacao_Geral[[#This Row],[ID Entidade]], Tabela_Clientes[ID_Cliente],Tabela_Clientes[Nome_Cliente],"Cliente não encontrado"),_xlfn.XLOOKUP(Tabela_Movimentacao_Geral[[#This Row],[ID Entidade]], Tabela_Fornecedores[ID_Fornecedor], Tabela_Fornecedores[Nome_Fantasia], "Fornecedor não encontrado")) -> TechFlow Solucoes | F30: =IF( $O$7="Desbloqueado", "PROD"&TEXT(RANDBETWEEN(1,200),"000"), Tabela_Movimentacao_Geral[[#This Row],[ID Produto]] ) -> PROD057 | G30: =_xlfn.XLOOKUP(Tabela_Movimentacao_Geral[[#This Row],[ID Produto]], Tabela_Produtos[ID_Produto],Tabela_Produtos[Descricao_Produto],"Produto não encontrado") -> Caneta Esferografica Azul | H30: {=IF( $O$7="Desbloqueado", _xlfn.LET( _xlpm.saldo_atual, SUM(($C$2:$C29="Entrada")*($F$2:$F29=Tabela_Movimentacao_Geral[[#This Row],[ID Produto]])*($H$2:$H29) - ($C$2:$C29="Saida")*($F$2:$F29=Tabela_Movimentacao_Geral[[#This Row],[ID Produto]])*($H$2:$H29)), _xlpm.estoque_minimo, _xlfn.XLOOKUP(Tabela_Movimentacao_Geral[[#This Row],[ID Produto]], Tabela_Produtos[ID_Produto], Tabela_Produtos[Estoque_Minimo], 0), IF( _xlpm.saldo_atual > _xlpm.estoque_minimo, IF( Tabela_Movimentacao_Geral[[#This Row],[Tipo Fluxo]]="Saida", RANDBETWEEN(1, _xlpm.saldo_atual), RANDBETWEEN(1, 100) ), IF( Tabela_Movimentacao_Geral[[#This Row],[Tipo Fluxo]]="Saida", RANDBETWEEN(1, _xlpm.saldo_atual), IF( _xlpm.saldo_atual < 0, ABS(_xlpm.saldo_atual) + _xlpm.estoque_minimo + RANDBETWEEN(1, 100), _xlpm.estoque_minimo - _xlpm.saldo_atual + RANDBETWEEN(1, 100) ) ) ) ), Tabela_Movimentacao_Geral[[#This Row],[Quantidade]] )} -> 574 | I30: =_xlfn.XLOOKUP(Tabela_Movimentacao_Geral[[#This Row],[ID Produto]], Tabela_Produtos[ID_Produto],Tabela_Produtos[Preco_Unitario_Venda]) -> 1.5 | J30: =Tabela_Movimentacao_Geral[[#This Row],[Quantidade]] * Tabela_Movimentacao_Geral[[#This Row],[Valor Unitário]] -> 861 | K30: =IF( $O$7="Desbloqueado", CHOOSE(RANDBETWEEN(1,3),"Pago","Pendente","Atrasado"), Tabela_Movimentacao_Geral[[#This Row],[Status Financeiro]] ) -> Pago | L30: =IF( $O$7="Desbloqueado", CHOOSE(RANDBETWEEN(1,3),"Entregue","Em Rota","Aguardando"), Tabela_Movimentacao_Geral[[#This Row],[Status Logistico]] ) -> Entregue | M30: =IF( $O$7="Desbloqueado", IF( Tabela_Movimentacao_Geral[[#This Row],[Tipo Fluxo]]="Entrada", Tabela_Movimentacao_Geral[[#This Row],[Data]] + _xlfn.XLOOKUP(Tabela_Movimentacao_Geral[[#This Row],[ID Entidade]],Tabela_Fornecedores[ID_Fornecedor],Tabela_Fornecedores[Lead_Time]), "N/A" ), Tabela_Movimentacao_Geral[[#This Row],[Previsão de Entrega]] ) -> 45684 | P30: =8 -> 8
